<?xml version="1.0"?>
<!-- Revolute-Revolute Manipulator -->
<robot name="rrbot" xmlns:xacro="http://www.ros.org/wiki/xacro">

  <!-- Constants for robot dimensions -->
  <xacro:property name="PI" value="3.1415926535897931"/>
  <xacro:property name="mass" value="1" /> <!-- arbitrary value for mass -->
  <xacro:property name="r" value="0.05" /> <!-- Circle dimensions (PI*radius^2) of Rods -->
  <xacro:property name="l1" value="0.25" /> <!-- Link 1 -->
  <xacro:property name="l2" value="1" /> <!-- Link 2 -->
  <xacro:property name="l3" value="1" /> <!-- Link 3 -->
  <xacro:property name="camera_link" value="0.05" /> <!-- Size of square 'camera' cylinder -->
  <xacro:property name="axel_offset" value="0.05" /> <!-- Space btw top of beam and the each joint -->

  <!-- Import all Gazebo-customization elements, including Gazebo colors -->
  <xacro:include filename="$(find rifo_gazebo)/urdf/rrbot.gazebo" />
  <!-- Import Rviz colors -->
  <xacro:include filename="$(find rifo_gazebo)/urdf/materials.xacro" />

  <!-- Used for fixing robot to Gazebo 'base_link' -->
  <link name="world"/>

  <joint name="fixed" type="fixed">
    <parent link="world"/>
    <child link="base"/>
    <!-- <origin xyz="0 0 0" rpy="0 0 0"/>
    <axis xyz="0 0 1"/>
    <dynamics damping="0.7"/> -->
  </joint>

  <!-- Base Link -->

  <link name="base">
    <collision>
      <origin xyz="0 0 ${l1/2}" rpy="0 0 0"/>
      <geometry>
	      <cylinder length="${l1}" radius="${r}"/>
      </geometry>
    </collision>

    <visual>
      <origin xyz="0 0 ${l1/2}" rpy="0 0 0"/>
      <geometry>
        <cylinder length="${l1}" radius="${r}"/>
      </geometry>
      <material name="orange"/>
    </visual>

    <inertial>
      <origin xyz="0 0 ${l1/2}" rpy="0 0 0"/>
      <mass value="${mass}"/>
      <inertia
	  ixx="${mass / 12.0 * (3*r*r + l1*l1)}" ixy="0.0" ixz="0.0"
	  iyy="${mass / 12.0 * (l1*l1 + 3*r*r)}" iyz="0.0"
	  izz="${mass / 12.0 * (3*r*r)}"/>
    </inertial>
  </link>

  <joint name="joint1" type="continuous">
    <parent link="base"/>
    <child link="link1"/>
    <origin xyz="0 0 ${l1}" rpy="0 0 0"/>
    <axis xyz="0 0 1"/>
    <dynamics damping="0.7"/>
  </joint>

  <link name="link1">
    <collision>
      <origin xyz="0 0 ${l1/2}" rpy="0 0 0"/>
      <geometry>
	      <cylinder length="${l1}" radius="${r}"/>
      </geometry>
    </collision>

    <visual>
      <origin xyz="0 0 ${l1/2}" rpy="0 0 0"/>
      <geometry>
	      <cylinder length="${l1}" radius="${r}"/>
      </geometry>
      <material name="orange"/>
    </visual>

    <inertial>
      <origin xyz="0 0 ${l1/2}" rpy="0 0 0"/>
      <mass value="${mass}"/>
      <inertia
	  ixx="${mass / 12.0 * (3*r*r + l1*l1)}" ixy="0.0" ixz="0.0"
	  iyy="${mass / 12.0 * (l1*l1 + 3*r*r)}" iyz="0.0"
	  izz="${mass / 12.0 * (3*r*r)}"/>
    </inertial>
  </link>

  <joint name="joint2" type="continuous">
    <parent link="link1"/>
    <child link="link2"/>
    <origin xyz="0 0 ${l1}" rpy="0 0 0"/>
    <axis xyz="0 1 0"/>
    <dynamics damping="0.7"/>
  </joint>

  <!-- Middle Link -->
  <link name="link2">
    <collision>
      <origin xyz="0 0 ${l2/2}" rpy="0 0 0"/>
      <geometry>
	<cylinder length="${l2}" radius="${r}"/>
      </geometry>
    </collision>

    <visual>
      <origin xyz="0 0 ${l2/2}" rpy="0 0 0"/>
      <geometry>
	<cylinder length="${l2}" radius="${r}"/>
      </geometry>
      <material name="black"/>
    </visual>

    <inertial>
      <origin xyz="0 0 ${l2/2}" rpy="0 0 0"/>
      <mass value="${mass}"/>
      <inertia
	  ixx="${mass / 12.0 * (3*r*r + l2*l2)}" ixy="0.0" ixz="0.0"
	  iyy="${mass / 12.0 * (l2*l2 + 3*r*r)}" iyz="0.0"
	  izz="${mass / 12.0 * (3*r*r)}"/>
    </inertial>
  </link>

  <joint name="joint3" type="continuous">
    <parent link="link2"/>
    <child link="link3"/>
    <origin xyz="0 0 ${l2}" rpy="0 0 0"/>
    <axis xyz="0 1 0"/>
    <dynamics damping="0.7"/>
  </joint>

  <!-- Top Link -->
  <link name="link3">
    <collision>
      <origin xyz="0 0 ${l3/2}" rpy="0 0 0"/>
      <geometry>
	<cylinder length="${l3}" radius="${r}"/>
      </geometry>
    </collision>

    <visual>
      <origin xyz="0 0 ${l3/2}" rpy="0 0 0"/>
      <geometry>
	<cylinder length="${l3}" radius="${r}"/>
      </geometry>
      <material name="orange"/>
    </visual>

    <inertial>
      <origin xyz="0 0 ${l3/2}" rpy="0 0 0"/>
      <mass value="${mass}"/>
      <inertia
	  ixx="${mass / 12.0 * (3*r*r + l3*l3)}" ixy="0.0" ixz="0.0"
	  iyy="${mass / 12.0 * (l3*l3 + 3*r*r)}" iyz="0.0"
	  izz="${mass / 12.0 * (3*r*r)}"/>
    </inertial>
  </link>

  <joint name="end_effector_fixed" type="fixed">
    <parent link="link3"/>
    <child link="end_effector"/>
    <origin xyz="0 0 ${l2}" rpy="0 0 0"/>
  </joint>

<!-- End_effector -->
  <link name="end_effector">
    <collision>
      <origin xyz="0 0.5 0.125" rpy="0 0 0"/>
      <geometry>
	      <box size="0.25 0.25 0.25"/>
      </geometry>
    </collision>

    <visual>
      <origin xyz="0 0.5 0.125" rpy="0 0 0"/>
      <geometry>
	      <box size="0.25 0.25 0.25"/>
      </geometry>
      <material name="orange"/>
    </visual>

    <inertial>
      <origin xyz="0 0 0" rpy="0 0 0"/>
      <mass value="0"/>
      <inertia
	  ixx="0.01" ixy="0.0" ixz="0.0"
	  iyy="0.01" iyz="0.0"
	  izz="0.01"/>
    </inertial>
  </link>

  
  <!-- <hardwareInterface>hardware_interface/EffortJointInterface</hardwareInterface> -->
  <transmission name="tran1">
    <type>transmission_interface/SimpleTransmission</type>
    <joint name="joint1">
      <hardwareInterface>hardware_interface/PositionJointInterface</hardwareInterface>
    </joint>
    <actuator name="motor1">
      <hardwareInterface>hardware_interface/PositionJointInterface</hardwareInterface>
      <mechanicalReduction>1</mechanicalReduction>
    </actuator>
  </transmission>

  <transmission name="tran2">
    <type>transmission_interface/SimpleTransmission</type>
    <joint name="joint2">
      <hardwareInterface>hardware_interface/PositionJointInterface</hardwareInterface>
    </joint>
    <actuator name="motor2">
      <hardwareInterface>hardware_interface/PositionJointInterface</hardwareInterface>
      <mechanicalReduction>1</mechanicalReduction>
    </actuator>
  </transmission>

  <transmission name="tran3">
    <type>transmission_interface/SimpleTransmission</type>
    <joint name="joint3">
      <hardwareInterface>hardware_interface/PositionJointInterface</hardwareInterface>
    </joint>
    <actuator name="motor3">
      <hardwareInterface>hardware_interface/PositionJointInterface</hardwareInterface>
      <mechanicalReduction>1</mechanicalReduction>
    </actuator>
  </transmission>

</robot>
